Workbook

Sheet Mit overblik
A1: Mit overblik
A2: Måling | B2: Værdi
A3: Valgt uge | B3: 2026-W07
A4: Kapacitet (timer) | B4: =IFERROR(INDEX(Ugekapacitet!$D$2:$D$60,MATCH(TRIM($B$3),Ugekapacitet!$A$2:$A$60,0)),0) -> 16.125
A5: Planlagt load (timer) | B5: =SUMIFS('Mine opgaver'!$B$3:$B$200,'Mine opgaver'!$F$3:$F$200,$B$3,'Mine opgaver'!$E$3:$E$200,"<>Færdig") -> 0
A6: Udnyttelse | B6: =B5/B4 -> 0
A7: Status | B7: =IF(B6>1, "For meget", IF(B6>0.85, "Presset", "OK")) -> OK
A11: Status | B11: =IF(B6=0,"Ingen planlagte opgaver",IF(B6>1,"Over kapacitet – der skal fravælges eller rykkes",IF(B6>0.85,"Højt pres – begrænset fleksibilitet","Inden for kapacitet"))) -> Ingen planlagte opgaver

Sheet Mine opgaver
A1: Mine opgaver
A2: Opgave | B2: Estimat (timer) | C2: Planlagt opstartsuge | D2: Prioritet | E2: Status | F2: Aktuel uge | G2: Deadline | H2: Kommentarer
I5: Forklaring
I6: Hver række en opgave

Sheet Ugekapacitet
A1: Uge | B1: Normtid | C1: Ferie/fravær i timer | D1: Ugekapacitet
A2: 2026-W01 | B2: 37 | C2: 37 | D2: =(B2-C2)*Kapacitet!B$7 -> 0
A3: 2026-W02 | B3: 37 | C3: 37 | D3: =(B3-C3)*Kapacitet!B$7 -> 0
A4: 2026-W03 | B4: 37 | C4: 33 | D4: =(B4-C4)*Kapacitet!B$7 -> 3
A5: 2026-W04 | B5: 37 | C5: 31 | D5: =(B5-C5)*Kapacitet!B$7 -> 4.5
A6: 2026-W05 | B6: 37 | C6: =B6-12 -> 25 | D6: =(B6-C6)*Kapacitet!B$7 -> 9
A7: 2026-W06 | B7: 37 | C7: =B7-21 -> 16 | D7: =(B7-C7)*Kapacitet!B$7 -> 15.75
A8: 2026-W07 | B8: 37 | C8: =B8-21.5 -> 15.5 | D8: =(B8-C8)*Kapacitet!B$7 -> 16.125
A9: 2026-W08 | B9: 37 | C9: =B9-25 -> 12 | D9: =(B9-C9)*Kapacitet!B$7 -> 18.75
A10: 2026-W09 | B10: 37 | C10: =B10-30 -> 7 | D10: =(B10-C10-Kapacitet!B4)*Kapacitet!B$7 -> 15
A11: 2026-W10 | B11: 37 | C11: =B11-35 -> 2 | D11: =(B11-C11-Kapacitet!B4)*Kapacitet!B$7 -> 18.75
A12: 2026-W11 | B12: 37 | C12: 0 | D12: =(B12-C12-Kapacitet!B4)*Kapacitet!B$7 -> 20.25
A13: 2026-W12 | B13: 37 | C13: =B13-37 -> 0 | D13: =(B13-C13-Kapacitet!B4)*Kapacitet!B$7 -> 20.25
A14: 2026-W13 | B14: 37 | C14: =B14-0 -> 37 | D14: =(B14-C14)*Kapacitet!B$7 -> 0
A15: 2026-W14 | B15: 37 | C15: =B16-15 -> 22 | D15: =(B15-C15)*Kapacitet!B$7 -> 11.25
A16: 2026-W15 | B16: 37 | C16: 37 | D16: =(B16-C16)*Kapacitet!B$7 -> 0
A17: 2026-W16 | B17: 37 | C17: 0 | D17: =(B17-C17-Kapacitet!B4)*Kapacitet!B$7 -> 20.25
A18: 2026-W17 | B18: 37 | C18: 0 | D18: =(B18-C18-Kapacitet!B4)*Kapacitet!B$7 -> 20.25
A19: 2026-W18 | B19: 37 | C19: 0 | D19: =(B19-C19-Kapacitet!B4)*Kapacitet!B$7 -> 20.25
A20: 2026-W19 | B20: 37 | C20: 0 | D20: =(B20-C20-Kapacitet!B$4)*Kapacitet!B$7 -> 20.25
A21: 2026-W20 | B21: 37 | C21: 15 | D21: =(B21-C21-Kapacitet!B$4)*Kapacitet!B$7 -> 9
A22: 2026-W21 | B22: 37 | C22: 0 | D22: =(B22-C22-Kapacitet!B$4)*Kapacitet!B$7 -> 20.25
A23: 2026-W22 | B23: 37 | C23: 37 | D23: =(B23-C23-Kapacitet!B$4)*Kapacitet!B$7 -> -7.5
A24: 2026-W23 | B24: 37 | C24: 7.5 | D24: =(B24-C24-Kapacitet!B$4)*Kapacitet!B$7 -> 14.625
A25: 2026-W24 | B25: 37 | C25: 0 | D25: =(B25-C25-Kapacitet!B$4)*Kapacitet!B$7 -> 20.25
A26: 2026-W25 | B26: 37 | C26: 0 | D26: =(B26-C26-Kapacitet!B$4)*Kapacitet!B$7 -> 20.25
A27: 2026-W26 | B27: 37 | C27: 0 | D27: =(B27-C27-Kapacitet!B$4)*Kapacitet!B$7 -> 20.25
A28: 2026-W27 | B28: 37 | C28: 0 | D28: =(B28-C28-Kapacitet!B$4)*Kapacitet!B$7 -> 20.25
A29: 2026-W28 | B29: 37 | C29: 37 | D29: =(B29-C29)*Kapacitet!B$7 -> 0
A30: 2026-W29 | B30: 37 | C30: =B30-0 -> 37 | D30: =(B30-C30)*Kapacitet!B$7 -> 0
A31: 2026-W30 | B31: 37 | C31: =B31-0 -> 37 | D31: =(B31-C31)*Kapacitet!B$7 -> 0
A32: 2026-W31 | B32: 37 | C32: 0 | D32: =(B32-C32-Kapacitet!B$4)*Kapacitet!B$7 -> 20.25
A33: 2026-W32 | B33: 37 | C33: 0 | D33: =(B33-C33-Kapacitet!B$4)*Kapacitet!B$7 -> 20.25
A34: 2026-W33 | B34: 37 | C34: 0 | D34: =(B34-C34-Kapacitet!B$4)*Kapacitet!B$7 -> 20.25
A35: 2026-W34 | B35: 37 | C35: 0 | D35: =(B35-C35-Kapacitet!B$4)*Kapacitet!B$7 -> 20.25
A36: 2026-W35 | B36: 37 | C36: 0 | D36: =(B36-C36-Kapacitet!B$4)*Kapacitet!B$7 -> 20.25
A37: 2026-W36 | B37: 37 | C37: 0 | D37: =(B37-C37-Kapacitet!B$4)*Kapacitet!B$7 -> 20.25
A38: 2026-W37 | B38: 37 | C38: 0 | D38: =(B38-C38-Kapacitet!B$4)*Kapacitet!B$7 -> 20.25
A39: 2026-W38 | B39: 37 | C39: 0 | D39: =(B39-C39-Kapacitet!B$4)*Kapacitet!B$7 -> 20.25
A40: 2026-W39 | B40: 37 | C40: 0 | D40: =(B40-C40-Kapacitet!B$4)*Kapacitet!B$7 -> 20.25
...

Sheet Tabeller
A1: Tabeller
A2: Prioritet | B2: Status
A4: 1 | B4: Planlagt
A5: 2 | B5: I gang
A6: 3 | B6: Udsat
B7: Ikke startet
B8: Færdig

Sheet Kapacitet
A1: Min kapacitet
A2: Parameter | B2: Timer
A3: Arbejdstiver pr. uge | B3: =37+2.5 -> 39.5
A4: Tid til ad hoc-opgaver | B4: 10
A5: Faste pauser | B5: 2.5
A6: Netto arbejdstid | B6: =B3-B5-B4 -> 27
A7: Fokus faktor | B7: 0.75
A8: Planlægningskapacitet | B8: =B6*B7 -> 20.25
